<?xml version="1.0"?>
<robot xmlns:xacro="http://www.ros.org/wiki/xacro">

  <xacro:macro name="robot" params="a L R r">

    <link name="base_link">
    </link>
  
      <!-- Body -->
      <link name="chassis">
        <visual>
          <origin rpy="0 0 -1.57" xyz="1.384 0 0.55"/>
          <geometry>
            <mesh filename="package://itav_description/meshes/body.stl"/>
          </geometry>
          <material name="silver"/>
        </visual>
  
        <inertial>
          <mass value="1"/>
          <origin rpy="0 0 0" xyz="0 0 0"/>
          <inertia ixx="0.1" ixy="0" ixz="0" iyy="0.1" iyz="0" izz="0.1"/>
        </inertial>
    
        <collision>
          <geometry>
            <box size="0.01 0.01 0.01"/>
          </geometry>
        </collision>
      </link>
  
      <joint name="base_link_joint" type="fixed">
        <origin rpy="0 0 0" xyz="0 0 0" />
        <parent link="base_link" />
        <child link="chassis" />
      </joint>

      <!-- Fork -->
      <link name="fork_link">
        <visual>
          <origin rpy="1.57 0 -1.57" xyz="0 0 0"/>
          <geometry>
            <mesh filename="package://itav_description/meshes/fork.stl"/>
          </geometry>
          <material name="silver"/>
        </visual>
      </link>
  
      <joint name="chassis_fork_joint" type="fixed">
        <origin rpy="0 0 0" xyz="0.7 0 0.2" />
        <parent link="chassis" />
        <child link="fork_link" />
      </joint>

    <!-- Front Link -->
    <link name="front_link">      
      <visual>
        <origin rpy="0 0 0" xyz="0 0 0"/>
        <geometry>
          <box size="0.01 0.01 0.01"/>
        </geometry>
        <material name="black"/>
      </visual>
  
      <inertial>
        <mass value="1"/>
        <origin rpy="0 0 0" xyz="0 0 0"/>
        <inertia ixx="0.1" ixy="0" ixz="0" iyy="0.1" iyz="0" izz="0.1"/>
      </inertial>
  
      <collision>
        <geometry>
          <box size="0.01 0.01 0.01"/>
        </geometry>
      </collision>
    </link>

    <joint name="front_joint" type="fixed">
      <origin rpy="0 0 0" xyz="${L} 0 0" />
      <parent link="chassis" />
      <child link="front_link" />
    </joint>
  
    <!-- Steering -->
    <link name="steering_link">      
      <visual>
        <origin rpy="0 0 0" xyz="0 0 0"/>
        <geometry>
          <box size="0.01 0.01 0.01"/>
        </geometry>
        <material name="black"/>
      </visual>
  
      <inertial>
        <mass value="1"/>
        <origin rpy="0 0 0" xyz="0 0 0"/>
        <inertia ixx="0.1" ixy="0" ixz="0" iyy="0.1" iyz="0" izz="0.1"/>
      </inertial>
  
      <collision>
        <geometry>
          <box size="0.01 0.01 0.01"/>
        </geometry>
      </collision>
    </link>
  
    <joint name="steering_joint" type="revolute">
      <origin rpy="0 0 0" xyz="0 ${-a} 0"/>
      <child link="steering_link"/>
      <parent link="front_link"/>
      <axis rpy="0 0 0" xyz="0 0 1"/>
      <limit lower="-1.4" upper="1.4"  effort="10000" velocity="1000"/>
      <joint_properties damping="10000.0" friction="100.0"/>
    </joint>
  
      <!-- Traction -->
      <link name="traction_link">      
        <visual>
          <origin rpy="0 1.5707 1.5707" xyz="0 0 0"/>
          <geometry>
            <cylinder length="0.095" radius="${R}"/>
          </geometry>
          <material name="black"/>
        </visual>
  
        <inertial>
          <origin rpy="0 1.5707 1.5707" xyz="0 0 0"/>
          <mass value="10"/>
          <origin rpy="0 0 0" xyz="0 0 0"/>
          <inertia ixx="0.04977083333333334" ixy="0" ixz="0" iyy="0.04977083333333334" iyz="0" izz="0.0845"/>
        </inertial>
    
        <collision>
          <origin rpy="0 1.5707 1.5707" xyz="0 0 0"/>
          <geometry>
            <cylinder length="0.095" radius="${R}"/>
          </geometry>
        </collision>
      </link>
    
      <joint name="traction_joint" type="continuous">
        <origin rpy="0 0 0" xyz="0 0 ${R - r}"/>
        <child link="traction_link"/>
        <parent link="steering_link"/>
        <axis rpy="0 0 0" xyz="0 1 0"/>
        <limit effort="1" velocity="1"/>
        <joint_properties damping="1000.0" friction="100000.0"/>
      </joint>
  
    <!-- Wheel Left -->
    <link name="left_wheel_link">      
      <visual>
        <origin rpy="0 1.5707 1.5707" xyz="0 0 0"/>
        <geometry>
          <cylinder length="0.06" radius="${r}"/>
        </geometry>
        <material name="black"/>
      </visual>
  
      <inertial>
        <origin rpy="0 1.5707 1.5707" xyz="0 0 0"/>
        <mass value="10"/>
        <origin rpy="0 0 0" xyz="0 0 0"/>
        <inertia ixx="0.0072025000000000014" ixy="0" ixz="0" iyy="0.0072025000000000014" iyz="0" izz="0.008405000000000001"/>
      </inertial>
  
      <collision>
        <origin rpy="0 1.5707 1.5707" xyz="0 0 0"/>
        <geometry>
          <cylinder length="0.06" radius="${r}"/>
        </geometry>
      </collision>
    </link>
  
    <joint name="left_wheel_joint" type="continuous">
      <origin rpy="0 0 0" xyz="0.045 0.187 0"/>
      <child link="left_wheel_link"/>
      <parent link="chassis"/>
      <axis rpy="0 0 0" xyz="0 1 0"/>
      <limit effort="10000" velocity="1000"/>
      <joint_properties damping="10000.0" friction="100000.0"/>
    </joint>
  
    <!-- Wheel Right -->
    <link name="right_wheel_link">      
        <visual>
          <origin rpy="0 1.5707 1.5707" xyz="0 0 0"/>
          <geometry>
            <cylinder length="0.06" radius="${r}"/>
          </geometry>
          <material name="black"/>
        </visual>
  
        <inertial>
          <origin rpy="0 1.5707 1.5707" xyz="0 0 0"/>
          <mass value="10"/>
          <origin rpy="0 0 0" xyz="0 0 0"/>
          <inertia ixx="0.0072025000000000014" ixy="0" ixz="0" iyy="0.0072025000000000014" iyz="0" izz="0.008405000000000001"/>
        </inertial>
    
        <collision>
          <origin rpy="0 1.5707 1.5707" xyz="0 0 0"/>
          <geometry>
            <cylinder length="0.06" radius="${r}"/>
          </geometry>
        </collision>
    </link>
  
    <joint name="right_wheel_joint" type="continuous">  
      <origin rpy="0 0 0" xyz="0.045 -0.187 0"/>
      <child link="right_wheel_link"/>
      <parent link="chassis"/>
      <axis rpy="0 0 0" xyz="0 1 0"/>
      <limit effort="10000" velocity="1000"/>
      <joint_properties damping="10000.0" friction="100000.0"/>
    </joint>
  
   <!-- Wheel Left Back -->
   <link name="left_wheel_back_link">      
    <visual>
      <origin rpy="0 1.5707 1.5707" xyz="0 0 0"/>
      <geometry>
        <cylinder length="0.06" radius="${r}"/>
      </geometry>
      <material name="black"/>
    </visual>
  
      <inertial>
        <origin rpy="0 1.5707 1.5707" xyz="0 0 0"/>
        <mass value="10"/>
        <origin rpy="0 0 0" xyz="0 0 0"/>
        <inertia ixx="0.0072025000000000014" ixy="0" ixz="0" iyy="0.0072025000000000014" iyz="0" izz="0.008405000000000001"/>
      </inertial>
  
    <collision>
      <origin rpy="0 1.5707 1.5707" xyz="0 0 0"/>
      <geometry>
        <cylinder length="0.06" radius="${r}"/>
      </geometry>
    </collision>
  </link>
  
  <joint name="left_wheel_back_joint" type="continuous">
    <origin rpy="0 0 0" xyz="-0.045 0.187 0"/>
    <child link="left_wheel_back_link"/>
    <parent link="chassis"/>
    <axis rpy="0 0 0" xyz="0 1 0"/>
    <limit effort="10000" velocity="1000"/>
    <joint_properties damping="10000.0" friction="100000.0"/>
  </joint>
  
  <!-- Wheel Right Back -->
  <link name="right_wheel_back_link">      
      <visual>
        <origin rpy="0 1.5707 1.5707" xyz="0 0 0"/>
        <geometry>
          <cylinder length="0.06" radius="${r}"/>
        </geometry>
        <material name="black"/>
      </visual>
  
      <inertial>
        <origin rpy="0 1.5707 1.5707" xyz="0 0 0"/>
        <mass value="10"/>
        <origin rpy="0 0 0" xyz="0 0 0"/>
        <inertia ixx="0.0072025000000000014" ixy="0" ixz="0" iyy="0.0072025000000000014" iyz="0" izz="0.008405000000000001"/>
      </inertial>
  
      <collision>
        <origin rpy="0 1.5707 1.5707" xyz="0 0 0"/>
        <geometry>
          <cylinder length="0.06" radius="${r}"/>
        </geometry>
      </collision>
  </link>

  <joint name="right_wheel_back_joint" type="continuous">  
    <origin rpy="0 0 0" xyz="-0.045 -0.187 0"/>
    <child link="right_wheel_back_link"/>
    <parent link="chassis"/>
    <axis rpy="0 0 0" xyz="0 1 0"/>
    <limit effort="10000" velocity="1000"/>
    <joint_properties damping="10000.0" friction="100000.0"/>
  </joint>

</xacro:macro>

</robot>